Workbook

Sheet Sheet1
A1: task_id | B1: statement | C1: code | D1: answer | E1: url | F1: input | G1: source | H1: data_id | I1: location | J1: last_error_details | K1: evaluated | L1: evaluated_array | M1: actual_verdict | N1: llm_verdict | O1: llm_answer | P1: llm_reason | Q1: final verdict
A2: 1 | B2: Anton has the integer x. He is interested what positive integer, which doesn't exceed x, has the maximum sum of digits. Your task is to help Anton and to find the integer that interests him. If there are several such integers, determine the biggest of them. -----Input----- The first line contains the positive integer x (1 ≤ x ≤ 10^18) — the integer which Anton has. -----Output----- Print the positive integer which doesn't exceed x and has the maximum sum of digits. If there are several such integers, print the biggest of them. Printed integer must not contain leading zeros. -----Examples----- Input 100 Output 99 Input 48 Output 48 Input 521 Output 499 | C2: def max_sum_digits(n): n = str(n) if len(n) == 1: return int(n) if '9' * len(n) <= n: return int('9' * len(n)) for i in range(len(n)): if n[i] != '9': return int(n[:i] + str(int(n[i]) - 1) + '9' * (len(n) - i - 1)) n = int(input().strip()) print(max_sum_digits(n)) | D2: C | E2: https://codeforces.com/problemset/problem/770/B | F2: ## Problem ### Problem Description Anton has the integer x. He is interested what positive integer, which doesn't exceed x, has the maximum sum of digits. Your task is to help Anton and to find the integer that interests him. If there are several such integers, determine the biggest of them. -----Input----- The first line contains the positive integer x (1 ≤ x ≤ 10^18) — the integer which Anton has. -----Output----- Print the positive integer which doesn't exceed x and has the maximum sum of digits. If there are several such integers, print the biggest of them. Printed integer must not contain leading zeros. -----Examples----- Input 100 Output 99 Input 48 Output 48 Input 521 Output 499 ### Solution code file content to be Judged def max_sum_digits(n): n = str(n) if len(n) == 1: return int(n) if '9' * len(n) <= n: return int('9' * len(n)) for i in range(len(n)): if n[i] != '9': return int(n[:i] + str(int(n[i]) - 1) + '9' * (len(n) - i - 1)) n = int(input().strip()) print(max_sum_digits(n)) | G2: gpt4 | H2: 9 | I2: APPS/test/0001 | J2: {'input': '9590999\n', 'expected': '8999999\n', 'actual': '9499999\n'} | K2: C | L2: 201 AC, 69 WA, 0 CE, 8 RE, 0 TLE | M2: RE | N2: AC | O2: A | P2: STEP 1: The problem requires finding the largest integer less than or equal to a given integer x that has the maximum sum of its digits. If there are multiple integers with the same maximum digit sum, the largest integer should be chosen. The input constraint is that x is a positive integer up to 10^18. STEP 2: The code defines a function `max_sum_digits(n)` which takes an integer n as input. It first converts n to a string. If n is a single-digit number, it returns n itself since it is the only number with the maximum digit sum. If the number composed entirely of 9s with the same length as n is less than or equal to n, it returns that number. Otherwise, it iterates over the digits of n, and for the first non-9 digit, it decrements that digit by 1 and replaces all subsequent digits with 9s, then returns this new number. STEP 3: The code is correct for the problem requirements. It correctly identifies the largest number with the maximum digit sum by either using a number composed entirely of 9s or by decrementing the first non-9 digit and filling the rest with 9s. STEP 4: Not applicable as the code is correct. STEP 5: Not applicable as the code is correct. The code correctly implements the logic to find the largest integer with the maximum sum of digits that does not exceed the given integer x. | Q2: =_xlfn.XLOOKUP(H2,'final verdict'!F:F,'final verdict'!AJ:AJ,"") -> Misjudged wrong answer as correct: wrong answer on many cases but correct on a majority (reason: judge predicted a wrong expected output)
A3: 2 | B3: Apart from having lots of holidays throughout the year, residents of Berland also have whole lucky years. Year is considered lucky if it has no more than 1 non-zero digit in its number. So years 100, 40000, 5 are lucky and 12, 3001 and 12345 are not. You are given current year in Berland. Your task is to find how long will residents of Berland wait till the next lucky year. -----Input----- The first line contains integer number n (1 ≤ n ≤ 10^9) — current year in Berland. -----Output----- Output amount of years from the current year to the next lucky one. -----Examples----- Input 4 Output 1 Input 201 Output 99 Input 4000 Output 1000 -----Note----- In the first example next lucky year is 5. In the second one — 300. In the third — 5000. | C3: n = int(input()) if n % 10 == 0: print(1) elif n % 100 == 0: print(10) elif n % 1000 == 0: print(100) elif n % 10000 == 0: print(1000) else: print(10000) | D3: B | E3: https://codeforces.com/problemset/problem/808/A | F3: ## Problem ### Problem Description Apart from having lots of holidays throughout the year, residents of Berland also have whole lucky years. Year is considered lucky if it has no more than 1 non-zero digit in its number. So years 100, 40000, 5 are lucky and 12, 3001 and 12345 are not. You are given current year in Berland. Your task is to find how long will residents of Berland wait till the next lucky year. -----Input----- The first line contains integer number n (1 ≤ n ≤ 10^9) — current year in Berland. -----Output----- Output amount of years from the current year to the next lucky one. -----Examples----- Input 4 Output 1 Input 201 Output 99 Input 4000 Output 1000 -----Note----- In the first example next lucky year is 5. In the second one — 300. In the third — 5000. ### Solution code file content to be Judged n = int(input()) if n % 10 == 0: print(1) elif n % 100 == 0: print(10) elif n % 1000 == 0: print(100) elif n % 10000 == 0: print(1000) else: print(10000) | G3: gemma | H3: 15 | I3: APPS/test/0002 | J3: {'input': '90900\n', 'expected': '9100\n', 'actual': ''} | K3: B | L3: 0 AC, 0 WA, 271 CE, 0 RE, 0 TLE | M3: CE | N3: WA | O3: C | P3: STEP 1: The problem requires finding the next 'lucky year' after a given year 'n'. A lucky year is defined as a year with no more than one non-zero digit. The task is to calculate how many years it will take to reach the next lucky year from the given year 'n'. STEP 2: Analyzing the code: - `n = int(input())`: Reads the input year and converts it to an integer. - `if n % 10 == 0:`: Checks if the year is a multiple of 10. If true, it prints 1, assuming the next lucky year is 1 year away. - `elif n % 100 == 0:`: Checks if the year is a multiple of 100. If true, it prints 10, assuming the next lucky year is 10 years away. - `elif n % 1000 == 0:`: Checks if the year is a multiple of 1000. If true, it prints 100, assuming the next lucky year is 100 years away. - `elif n % 10000 == 0:`: Checks if the year is a multiple of 10000. If true, it prints 1000, assuming the next lucky year is 1000 years away. - `else:`: If none of the above conditions are met, it prints 10000, assuming the next lucky year is 10000 years away. STEP 3: The code is incorrect. It does not correctly calculate the next lucky year based on the definition provided. The logic only checks for multiples of 10, 100, 1000, and 10000, which does not align with the requirement of having no more than one non-zero digit. STEP 4: A specific test case where the code fails is `n = 201`. The correct output should be 99, as the next lucky year is 300. However, the code will output 10000, which is incorrect. STEP 5: The root cause of the failure is that the code does not correctly identify the next lucky year based on the number of non-zero digits. It only checks for specific multiples, which does not cover all possible cases of lucky years. Verdict: WA (Wrong Answer) Answer: C | Q3: =_xlfn.XLOOKUP(H3,'final verdict'!F:F,'final verdict'!AJ:AJ,"") -> Misjudged compilation error as wrong answer: indentation issue
A4: 6 | B4: You are fighting with Zmei Gorynich — a ferocious monster from Slavic myths, a huge dragon-like reptile with multiple heads! $m$ Initially Zmei Gorynich has $x$ heads. You can deal $n$ types of blows. If you deal a blow of the $i$-th type, you decrease the number of Gorynich's heads by $min(d_i, curX)$, there $curX$ is the current number of heads. But if after this blow Zmei Gorynich has at least one head, he grows $h_i$ new heads. If $curX = 0$ then Gorynich is defeated. You can deal each blow any number of times, in any order. For example, if $curX = 10$, $d = 7$, $h = 10$ then the number of heads changes to $13$ (you cut $7$ heads off, but then Zmei grows $10$ new ones), but if $curX = 10$, $d = 11$, $h = 100$ then number of heads changes to $0$ and Zmei Gorynich is considered defeated. Calculate the minimum number of blows to defeat Zmei Gorynich! You have to answer $t$ independent queries. -----Input----- The first line contains one integer $t$ ($1 \le t \le 100$) – the number of queries. The first line of each query contains two integers $n$ and $x$ ($1 \le n \le 100$, $1 \le x \le 10^9$) — the number of possible types of blows and the number of heads Zmei initially has, respectively. The following $n$ lines of each query contain the descriptions of types of blows you can deal. The $i$-th line contains two integers $d_i$ and $h_i$ ($1 \le d_i, h_i \le 10^9$) — the description of the $i$-th blow. -----Output----- For each query print the minimum number of blows you have to deal to defeat Zmei Gorynich. If Zmei Gorynuch cannot be defeated print $-1$. -----Example----- Input 3 3 10 6 3 8 2 1 4 4 10 4 1 3 2 2 6 1 100 2 15 10 11 14 100 Output 2 3 -1 -----Note----- In the first query you can deal the first blow (after that the number of heads changes to $10 - 6 + 3 = 7$), and then deal the second blow. In the second query you just deal the first blow three times, and Zmei is defeated. In third query you can not defeat Zmei Gorynich. Maybe it's better to convince it to stop fighting? | C4: t = int(input()) for _ in range(t): n, x = map(int, input().split()) max_d = max_h = 0 for _ in range(n): d, h = map(int, input().split()) max_d = max(max_d, d) max_h = max(max_h, d - h) if x <= max_d: print(1) elif max_h <= 0: print(-1) else: print((x - max_d + max_h - 1) // max_h + 1) | D4: A | E4: https://codeforces.com/problemset/problem/1217/B | F4: ## Problem ### Problem Description You are fighting with Zmei Gorynich — a ferocious monster from Slavic myths, a huge dragon-like reptile with multiple heads! $m$ Initially Zmei Gorynich has $x$ heads. You can deal $n$ types of blows. If you deal a blow of the $i$-th type, you decrease the number of Gorynich's heads by $min(d_i, curX)$, there $curX$ is the current number of heads. But if after this blow Zmei Gorynich has at least one head, he grows $h_i$ new heads. If $curX = 0$ then Gorynich is defeated. You can deal each blow any number of times, in any order. For example, if $curX = 10$, $d = 7$, $h = 10$ then the number of heads changes to $13$ (you cut $7$ heads off, but then Zmei grows $10$ new ones), but if $curX = 10$, $d = 11$, $h = 100$ then number of heads changes to $0$ and Zmei Gorynich is considered defeated. Calculate the minimum number of blows to defeat Zmei Gorynich! You have to answer $t$ independent queries. -----Input----- The first line contains one integer $t$ ($1 \le t \le 100$) – the number of queries. The first line of each query contains two integers $n$ and $x$ ($1 \le n \le 100$, $1 \le x \le 10^9$) — the number of possible types of blows and the number of heads Zmei initially has, respectively. The following $n$ lines of each query contain the descriptions of types of blows you can deal. The $i$-th line contains two integers $d_i$ and $h_i$ ($1 \le d_i, h_i \le 10^9$) — the description of the $i$-th blow. -----Output----- For each query print the minimum number of blows you have to deal to defeat Zmei Gorynich. If Zmei Gorynuch cannot be defeated print $-1$. -----Example----- Input 3 3 10 6 3 8 2 1 4 4 10 4 1 3 2 2 6 1 100 2 15 10 11 14 100 Output 2 3 -1 -----Note----- In the first query you can deal the first blow (after that the number of heads changes to $10 - 6 + 3 = 7$), and then deal the second blow. In the second query you just deal the first blow three times, and Zmei is defeated. In third query you can not defeat Zmei Gorynich. Maybe it's better to convince it to stop fighting? ### Solution code file content to be Judged t = int(input()) for _ in range(t): n, x = map(int, input().split()) max_d = max_h = 0 for _ in range(n): d, h = map(int, input().split()) max_d = max(max_d, d) max_h = max(max_h, d - h) if x <= max_d: print(1) elif max_h <= 0: print(-1) else: print((x - max_d + max_h - 1) // max_h + 1) | G4: gpt4 | H4: 32 | I4: APPS/test/0006 | K4: A | L4: 224 AC, 0 WA, 0 CE, 0 RE, 0 TLE | M4: AC | N4: WA | O4: C | P4: STEP 1: The problem requires determining the minimum number of blows needed to defeat Zmei Gorynich, a monster with multiple heads. Each blow type reduces the number of heads by a certain amount and may cause the monster to grow new heads. The goal is to find the minimum number of blows to reduce the monster's heads to zero, or determine if it's impossible. STEP 2: The code begins by reading the number of test cases `t`. For each test case, it reads the number of blow types `n` and the initial number of heads `x`. It initializes `max_d` to track the maximum damage a single blow can do and `max_h` to track the maximum net damage (damage minus regrowth) a blow can achieve. It then iterates over each blow type, updating `max_d` and `max_h` accordingly. After processing all blow types, it checks if the monster can be defeated in one blow (`x <= max_d`). If not, it checks if any blow results in a net reduction of heads (`max_h > 0`). If no net reduction is possible, it prints `-1`. Otherwise, it calculates the minimum number of blows needed using the formula `(x - max_d + max_h - 1) // max_h + 1` and prints the result. STEP 3: The code is incorrect. It fails to correctly calculate the minimum number of blows in some cases. STEP 4: Consider the input: 1 2 15 10 11 14 100 The expected output is `-1` because no blow can reduce the heads to zero, but the code outputs `-1`, which is correct. However, the logic for calculating the number of blows is flawed in other cases. STEP 5: The root cause of the failure is the incorrect calculation of the number of blows needed. The formula `(x - max_d + max_h - 1) // max_h + 1` does not correctly account for the sequence of blows needed to reduce the heads to zero. The code assumes that the maximum damage blow is always used first, which may not be optimal. Additionally, the calculation of `max_h` as `d - h` is incorrect because it should consider the net effect of repeatedly using a blow type, not just the difference for a single blow. | Q4: =_xlfn.XLOOKUP(H4,'final verdict'!F:F,'final verdict'!AJ:AJ,"") -> Misjudged correct as wrong answer: rationale is incorrect (reason: judge predicted a wrong expected output)
A5: 11 | B5: Little Joty has got a task to do. She has a line of n tiles indexed from 1 to n. She has to paint them in a strange pattern. An unpainted tile should be painted Red if it's index is divisible by a and an unpainted tile should be painted Blue if it's index is divisible by b. So the tile with the number divisible by a and b can be either painted Red or Blue. After her painting is done, she will get p chocolates for each tile that is painted Red and q chocolates for each tile that is painted Blue. Note that she can paint tiles in any order she wants. Given the required information, find the maximum number of chocolates Joty can get. -----Input----- The only line contains five integers n, a, b, p and q (1 ≤ n, a, b, p, q ≤ 10^9). -----Output----- Print the only integer s — the maximum number of chocolates Joty can get. Note that the answer can be too large, so you should use 64-bit integer type to store it. In C++ you can use the long long integer type and in Java you can use long integer type. -----Examples----- Input 5 2 3 12 15 Output 39 Input 20 2 3 3 5 Output 51 | C5: def max_chocolates(): n, a, b, p, q = map(int, input().split()) lcm = a * b // math.gcd(a, b) red_tiles = n // a blue_tiles = n // b common_tiles = n // lcm red_chocolates = red_tiles * p blue_chocolates = blue_tiles * q common_chocolates = common_tiles * min(p, q) total_chocolates = red_chocolates + blue_chocolates - common_chocolates return total_chocolates import math print(max_chocolates()) | D5: A | E5: https://codeforces.com/problemset/problem/678/C | F5: ## Problem ### Problem Description Little Joty has got a task to do. She has a line of n tiles indexed from 1 to n. She has to paint them in a strange pattern. An unpainted tile should be painted Red if it's index is divisible by a and an unpainted tile should be painted Blue if it's index is divisible by b. So the tile with the number divisible by a and b can be either painted Red or Blue. After her painting is done, she will get p chocolates for each tile that is painted Red and q chocolates for each tile that is painted Blue. Note that she can paint tiles in any order she wants. Given the required information, find the maximum number of chocolates Joty can get. -----Input----- The only line contains five integers n, a, b, p and q (1 ≤ n, a, b, p, q ≤ 10^9). -----Output----- Print the only integer s — the maximum number of chocolates Joty can get. Note that the answer can be too large, so you should use 64-bit integer type to store it. In C++ you can use the long long integer type and in Java you can use long integer type. -----Examples----- Input 5 2 3 12 15 Output 39 Input 20 2 3 3 5 Output 51 ### Solution code file content to be Judged def max_chocolates(): n, a, b, p, q = map(int, input().split()) lcm = a * b // math.gcd(a, b) red_tiles = n // a blue_tiles = n // b common_tiles = n // lcm red_chocolates = red_tiles * p blue_chocolates = blue_tiles * q common_chocolates = common_tiles * min(p, q) total_chocolates = red_chocolates + blue_chocolates - common_chocolates return total_chocolates import math print(max_chocolates()) | G5: deepseekcoder | H5: 52 | I5: APPS/test/0011 | K5: A | L5: 185 AC, 0 WA, 0 CE, 0 RE, 0 TLE | M5: AC | N5: WA | O5: C | P5: STEP 1: The problem requires calculating the maximum number of chocolates Joty can get by painting tiles. Tiles are painted Red if their index is divisible by 'a' and Blue if divisible by 'b'. If a tile's index is divisible by both 'a' and 'b', it can be painted either Red or Blue. Joty receives 'p' chocolates for each Red tile and 'q' chocolates for each Blue tile. The goal is to maximize the chocolates received. STEP 2: The code begins by reading input values for n, a, b, p, and q. It calculates the least common multiple (LCM) of 'a' and 'b' using the formula `lcm = a * b // math.gcd(a, b)`. This LCM is used to determine the number of tiles that are divisible by both 'a' and 'b'. The code calculates: - `red_tiles` as the number of tiles divisible by 'a'. - `blue_tiles` as the number of tiles divisible by 'b'. - `common_tiles` as the number of tiles divisible by both 'a' and 'b'. It then calculates the chocolates: - `red_chocolates` as the chocolates from Red tiles. - `blue_chocolates` as the chocolates from Blue tiles. - `common_chocolates` as the chocolates from common tiles, using the minimum of 'p' and 'q' to avoid double counting. Finally, it calculates `total_chocolates` by adding `red_chocolates` and `blue_chocolates` and subtracting `common_chocolates` to avoid double counting the common tiles. STEP 3: The code is incorrect. It does not correctly maximize the chocolates because it subtracts `common_chocolates` using `min(p, q)`, which does not account for maximizing the chocolates from common tiles. STEP 4: A test case that causes the code to fail is: Input: 6 2 3 10 5 Expected Output: 30 STEP 5: The root cause of the failure is that the code subtracts `common_chocolates` using `min(p, q)`, which does not maximize the chocolates. Instead, for common tiles, it should choose the maximum of 'p' or 'q' to maximize the chocolates received. The correct approach should be: - Calculate `red_chocolates` as `(red_tiles - common_tiles) * p`. - Calculate `blue_chocolates` as `(blue_tiles - common_tiles) * q`. - Calculate `common_chocolates` as `common_tiles * max(p, q)`. - Then, `total_chocolates = red_chocolates + blue_chocolates + common_chocolates`. | Q5: =_xlfn.XLOOKUP(H5,'final verdict'!F:F,'final verdict'!AJ:AJ,"") -> Misjudged correct as wrong answer: rationale is incorrect (reason: judge predicted a wrong expected output)
A6: 11 | B6: Little Joty has got a task to do. She has a line of n tiles indexed from 1 to n. She has to paint them in a strange pattern. An unpainted tile should be painted Red if it's index is divisible by a and an unpainted tile should be painted Blue if it's index is divisible by b. So the tile with the number divisible by a and b can be either painted Red or Blue. After her painting is done, she will get p chocolates for each tile that is painted Red and q chocolates for each tile that is painted Blue. Note that she can paint tiles in any order she wants. Given the required information, find the maximum number of chocolates Joty can get. -----Input----- The only line contains five integers n, a, b, p and q (1 ≤ n, a, b, p, q ≤ 10^9). -----Output----- Print the only integer s — the maximum number of chocolates Joty can get. Note that the answer can be too large, so you should use 64-bit integer type to store it. In C++ you can use the long long integer type and in Java you can use long integer type. -----Examples----- Input 5 2 3 12 15 Output 39 Input 20 2 3 3 5 Output 51 | C6: n, a, b, p, q = map(int, input().split()) s = 0 for i in range(1, n+1): if i % a == 0 and i % b == 0: s += p + q elif i % a == 0: s += p elif i % b == 0: s += q print(s) | D6: B | E6: https://codeforces.com/problemset/problem/678/C | F6: ## Problem ### Problem Description Little Joty has got a task to do. She has a line of n tiles indexed from 1 to n. She has to paint them in a strange pattern. An unpainted tile should be painted Red if it's index is divisible by a and an unpainted tile should be painted Blue if it's index is divisible by b. So the tile with the number divisible by a and b can be either painted Red or Blue. After her painting is done, she will get p chocolates for each tile that is painted Red and q chocolates for each tile that is painted Blue. Note that she can paint tiles in any order she wants. Given the required information, find the maximum number of chocolates Joty can get. -----Input----- The only line contains five integers n, a, b, p and q (1 ≤ n, a, b, p, q ≤ 10^9). -----Output----- Print the only integer s — the maximum number of chocolates Joty can get. Note that the answer can be too large, so you should use 64-bit integer type to store it. In C++ you can use the long long integer type and in Java you can use long integer type. -----Examples----- Input 5 2 3 12 15 Output 39 Input 20 2 3 3 5 Output 51 ### Solution code file content to be Judged n, a, b, p, q = map(int, input().split()) s = 0 for i in range(1, n+1): if i % a == 0 and i % b == 0: s += p + q elif i % a == 0: s += p elif i % b == 0: s += q print(s) | G6: gemma | H6: 57 | I6: APPS/test/0011 | J6: {'input': '100 8 12 5 6\n', 'expected': '88\n', 'actual': ''} | K6: B | L6: 0 AC, 0 WA, 185 CE, 0 RE, 0 TLE | M6: CE | N6: WA | O6: C | P6: STEP 1: The problem requires calculating the maximum number of chocolates Joty can get by painting tiles in a specific pattern. Tiles are painted Red if their index is divisible by 'a' and Blue if divisible by 'b'. If a tile's index is divisible by both 'a' and 'b', it can be painted either Red or Blue. The goal is to maximize the chocolates, where each Red tile gives 'p' chocolates and each Blue tile gives 'q' chocolates. STEP 2: Analyzing the code: - The code reads five integers: n, a, b, p, q. - It initializes a variable 's' to 0 to store the total chocolates. - It iterates over each tile index from 1 to n. - For each index, it checks: - If the index is divisible by both 'a' and 'b', it adds both 'p' and 'q' to 's'. - If the index is divisible only by 'a', it adds 'p' to 's'. - If the index is divisible only by 'b', it adds 'q' to 's'. - Finally, it prints the total chocolates 's'. STEP 3: The code is incorrect. It adds both 'p' and 'q' for indices divisible by both 'a' and 'b', which is not optimal. Instead, it should add the maximum of 'p' and 'q' for such indices to maximize chocolates. STEP 4: A test case that causes the code to fail: - Input: 6 2 3 10 20 - Expected Output: 70 (indices 2, 4, 6 should be Red, and 3 should be Blue) - Actual Output: 80 (incorrect because it adds both 'p' and 'q' for index 6) STEP 5: The root cause of the failure is the logic that adds both 'p' and 'q' for indices divisible by both 'a' and 'b'. The correct approach is to add the maximum of 'p' and 'q' for such indices to ensure the maximum number of chocolates. Verdict: WA Answer: C | Q6: =_xlfn.XLOOKUP(H6,'final verdict'!F:F,'final verdict'!AJ:AJ,"") -> Misjudged compilation error as wrong answer: indentation issue
A7: 25 | B7: You are given matrix with n rows and n columns filled with zeroes. You should put k ones in it in such a way that the resulting matrix is symmetrical with respect to the main diagonal (the diagonal that goes from the top left to the bottom right corner) and is lexicographically maximal. One matrix is lexicographically greater than the other if the first different number in the first different row from the top in the first matrix is greater than the corresponding number in the second one. If there exists no such matrix then output -1. -----Input----- The first line consists of two numbers n and k (1 ≤ n ≤ 100, 0 ≤ k ≤ 10^6). -----Output----- If the answer exists then output resulting matrix. Otherwise output -1. -----Examples----- Input 2 1 Output 1 0 0 0 Input 3 2 Output 1 0 0 0 1 0 0 0 0 Input 2 5 Output -1 | C7: n, k = map(int, input().split()) if k > n*(n-1)//2: print("-1") else: matrix = [[0]*n for _ in range(n)] count = 0 for i in range(n): for j in range(i+1): if count < k: matrix[i][j] = 1 count += 1 for i in range(n-1, -1, -1): for j in range(n-1, i, -1): if count < k: matrix[i][j] = 1 count += 1 for i in range(n): print(" ".join(map(str, matrix[i])) | D7: B | E7: https://codeforces.com/problemset/problem/803/A | F7: ## Problem ### Problem Description You are given matrix with n rows and n columns filled with zeroes. You should put k ones in it in such a way that the resulting matrix is symmetrical with respect to the main diagonal (the diagonal that goes from the top left to the bottom right corner) and is lexicographically maximal. One matrix is lexicographically greater than the other if the first different number in the first different row from the top in the first matrix is greater than the corresponding number in the second one. If there exists no such matrix then output -1. -----Input----- The first line consists of two numbers n and k (1 ≤ n ≤ 100, 0 ≤ k ≤ 10^6). -----Output----- If the answer exists then output resulting matrix. Otherwise output -1. -----Examples----- Input 2 1 Output 1 0 0 0 Input 3 2 Output 1 0 0 0 1 0 0 0 0 Input 2 5 Output -1 ### Solution code file content to be Judged n, k = map(int, input().split()) if k > n*(n-1)//2: print("-1") else: matrix = [[0]*n for _ in range(n)] count = 0 for i in range(n): for j in range(i+1): if count < k: matrix[i][j] = 1 count += 1 for i in range(n-1, -1, -1): for j in range(n-1, i, -1): if count < k: matrix[i][j] = 1 count += 1 for i in range(n): print(" ".join(map(str, matrix[i])) | G7: wizardcoder | H7: 115 | I7: APPS/test/0025 | J7: {'input': '100 10001\n', 'expected': '-1\n', 'actual': ''} | K7: B | L7: 0 AC, 0 WA, 156 CE, 0 RE, 0 TLE | M7: CE | N7: WA | O7: C | P7: STEP 1: The problem requires creating an n x n matrix with k ones such that the matrix is symmetrical with respect to the main diagonal and is lexicographically maximal. If it's not possible to place k ones, the output should be -1. The constraints are 1 ≤ n ≤ 100 and 0 ≤ k ≤ 10^6. STEP 2: Analyzing the code: - Line 1: Reads the input values n and k. - Line 3: Checks if k is greater than n*(n-1)//2. This condition is incorrect because it checks if k is greater than the number of off-diagonal elements, but it should check if k is greater than n*n (the total number of elements in the matrix) since we can place ones on the diagonal as well. - Line 4: If the above condition is true, it prints "-1". This is incorrect because the condition itself is wrong. - Line 6: Initializes an n x n matrix filled with zeroes. - Line 7: Initializes a counter `count` to track the number of ones placed. - Lines 8-12: Iterates over the matrix to place ones in the lower triangle including the diagonal. This loop is correct for placing ones in the lower triangle. - Lines 13-17: Iterates over the matrix to place ones in the upper triangle excluding the diagonal. This loop is incorrect because it doesn't ensure symmetry with respect to the main diagonal. - Lines 18-19: Prints the matrix row by row. STEP 3: The code is incorrect because it does not correctly check the condition for when it's impossible to place k ones, and it does not ensure the matrix is symmetrical with respect to the main diagonal. STEP 4: A test case that causes the code to fail is n = 2, k = 3. The code will output a matrix with 3 ones, which is impossible for a 2x2 matrix. STEP 5: The root cause of the failure is the incorrect condition for checking if k ones can be placed and the incorrect logic for ensuring the matrix is symmetrical with respect to the main diagonal. | Q7: =_xlfn.XLOOKUP(H7,'final verdict'!F:F,'final verdict'!AJ:AJ,"") -> Misjudged compilation error as wrong answer: bracket mismatch
A8: 28 | B8: The All-Berland National Olympiad in Informatics has just ended! Now Vladimir wants to upload the contest from the Olympiad as a gym to a popular Codehorses website. Unfortunately, the archive with Olympiad's data is a mess. For example, the files with tests are named arbitrary without any logic. Vladimir wants to rename the files with tests so that their names are distinct integers starting from 1 without any gaps, namely, "1", "2", ..., "n', where n is the total number of tests. Some of the files contain tests from statements (examples), while others contain regular tests. It is possible that there are no examples, and it is possible that all tests are examples. Vladimir wants to rename the files so that the examples are the first several tests, all all the next files contain regular tests only. The only operation Vladimir can perform is the "move" command. Vladimir wants to write a script file, each of the lines in which is "move file_1 file_2", that means that the file "file_1" is to be renamed to "file_2". If there is a file "file_2" at the moment of this line being run, then this file is to be rewritten. After the line "move file_1 file_2" the file "file_1" doesn't exist, but there is a file "file_2" with content equal to the content of "file_1" before the "move" command. Help Vladimir to write the script file with the minimum possible number of lines so that after this script is run: all examples are the first several tests having filenames "1", "2", ..., "e", where e is the total number of examples; all other files contain regular tests with filenames "e + 1", "e + 2", ..., "n", where n is the total number of all tests. -----Input----- The first line contains single integer n (1 ≤ n ≤ 10^5) — the number of files with tests. n lines follow, each describing a file with test. Each line has a form of "name_i type_i", where "name_i" is the filename, and "type_i" equals "1", if the i-th file contains an example test, and "0" if it contains a regular test. Filenames of each file are strings of digits and small English letters with length from 1 to 6 characters. The filenames are guaranteed to be distinct. -----Output----- In the first line print the minimum number of lines in Vladimir's script file. After that print the script file, each line should be "move file_1 file_2", where "file_1" is an existing at the moment of this line being run filename, and "file_2" — is a string of digits and small English letters with length from 1 to 6. -----Examples----- Input 5 01 0 2 1 2extra 0 3 1 99 0 Output 4 move 3 1 move 01 5 move 2extra 4 move 99 3 Input 2 1 0 2 1 Output 3 move 1 3 move 2 1 move 3 2 Input 5 1 0 11 1 111 0 1111 1 11111 0 Output 5 move 1 5 move 11 1 move 1111 2 move 111 4 move 11111 3 | C8: import sys # Read the number of files from standard input n = int(input()) # Initialize the minimum number of lines required for the script min_lines = n # Read the files and their types from standard input files = [] for _ in range(n): file_name = input() type_ = input() files.append((file_name, type_)) # Rename the examples to the first few numbers examples = [file_ for file_ in files if file_.0 == "1"] example_indices = [i for i, file_ in enumerate(files) if file_.0 == "1"] min_lines = min(min_lines, len(example_indices)) # Rename the remaining files remaining_files = [file_ for file_ in files if file_.0 != "1"] for i in range(len(remaining_files)): file_name = remaining_files[i] new_file_name = str(i + 1) print("move", file_name, new_file_name) min_lines = min(min_lines, 1) print(f"Minimum number of lines in the script: {min_lines}") | D8: B | E8: https://codeforces.com/problemset/problem/858/E | F8: ## Problem ### Problem Description The All-Berland National Olympiad in Informatics has just ended! Now Vladimir wants to upload the contest from the Olympiad as a gym to a popular Codehorses website. Unfortunately, the archive with Olympiad's data is a mess. For example, the files with tests are named arbitrary without any logic. Vladimir wants to rename the files with tests so that their names are distinct integers starting from 1 without any gaps, namely, "1", "2", ..., "n', where n is the total number of tests. Some of the files contain tests from statements (examples), while others contain regular tests. It is possible that there are no examples, and it is possible that all tests are examples. Vladimir wants to rename the files so that the examples are the first several tests, all all the next files contain regular tests only. The only operation Vladimir can perform is the "move" command. Vladimir wants to write a script file, each of the lines in which is "move file_1 file_2", that means that the file "file_1" is to be renamed to "file_2". If there is a file "file_2" at the moment of this line being run, then this file is to be rewritten. After the line "move file_1 file_2" the file "file_1" doesn't exist, but there is a file "file_2" with content equal to the content of "file_1" before the "move" command. Help Vladimir to write the script file with the minimum possible number of lines so that after this script is run: all examples are the first several tests having filenames "1", "2", ..., "e", where e is the total number of examples; all other files contain regular tests with filenames "e + 1", "e + 2", ..., "n", where n is the total number of all tests. -----Input----- The first line contains single integer n (1 ≤ n ≤ 10^5) — the number of files with tests. n lines follow, each describing a file with test. Each line has a form of "name_i type_i", where "name_i" is the filename, and "type_i" equals "1", if the i-th file contains an example test, and "0" if it contains a regular test. Filenames of each file are strings of digits and small English letters with length from 1 to 6 characters. The filenames are guaranteed to be distinct. -----Output----- In the first line print the minimum number of lines in Vladimir's script file. After that print the script file, each line should be "move file_1 file_2", where "file_1" is an existing at the moment of this line being run filename, and "file_2" — is a string of digits and small English letters with length from 1 to 6. -----Examples----- Input 5 01 0 2 1 2extra 0 3 1 99 0 Output 4 move 3 1 move 01 5 move 2extra 4 move 99 3 Input 2 1 0 2 1 Output 3 move 1 3 move 2 1 move 3 2 Input 5 1 0 11 1 111 0 1111 1 11111 0 Output 5 move 1 5 move 11 1 move 1111 2 move 111 4 move 11111 3 ### Solution code file content to be Judged import sys # Read the number of files from standard input n = int(input()) # Initialize the minimum number of lines required for the script min_lines = n # Read the files and their types from standard input files = [] for _ in range(n): file_name = input() type_ = input() files.append((file_name, type_)) # Rename the examples to the first few numbers examples = [file_ for file_ in files if file_.0 == "1"] example_indices = [i for i, file_ in enumerate(files) if file_.0 == "1"] min_lines = min(min_lines, len(example_indices)) # Rename the remaining files remaining_files = [file_ for file_ in files if file_.0 != "1"] for i in range(len(remaining_files)): file_name = remaining_files[i] new_file_name = str(i + 1) print("move", file_name, new_file_name) min_lines = min(min_lines, 1) print(f"Minimum number of lines in the script: {min_lines}") | G8: llama | H8: 127 | I8: APPS/test/0028 | J8: {'input': '2\n01 0\n02 1\n', 'expected': '2\nmove 02 1\nmove 01 2\n', 'actual': ''} | K8: B | L8: 0 AC, 0 WA, 146 CE, 0 RE, 0 TLE | M8: CE | N8: WA | O8: C | P8: STEP 1: The problem requires renaming files such that example files are named with consecutive integers starting from 1, followed by regular test files. The goal is to achieve this with the minimum number of 'move' operations. Each file is initially named arbitrarily, and the task is to rename them according to their type (example or regular test) while maintaining the order of examples first. STEP 2: Analyzing the code: - The code starts by reading the number of files `n` from input. - It initializes `min_lines` to `n`, which is intended to track the minimum number of move operations. - It reads the file names and types into a list `files`. - It attempts to separate example files from regular files using list comprehensions. - It calculates `example_indices` to track indices of example files. - It attempts to rename remaining files, but the logic is flawed. STEP 3: The code is incorrect. It does not correctly handle the input format, and the logic for renaming files is not implemented correctly. Specifically, the code attempts to access `file_.0` which is incorrect syntax for accessing tuple elements in Python. Additionally, the logic for renaming files is incomplete and does not follow the problem requirements. STEP 4: A test case that would cause the code to fail is: ``` 3 file1 1 file2 0 file3 1 ``` This input would cause the code to fail due to incorrect tuple access and incomplete logic. STEP 5: The root cause of the failure is the incorrect syntax for accessing tuple elements (`file_.0` instead of `file_[0]`), and the incomplete logic for renaming files according to the problem requirements. The code does not correctly separate and rename example and regular files, nor does it handle the input format correctly. Verdict: The code has logical and execution issues, leading to a Wrong Answer (WA). | Q8: =_xlfn.XLOOKUP(H8,'final verdict'!F:F,'final verdict'!AJ:AJ,"") -> Misjudged compilation error as wrong answer: illegal expression (reason: illegal variable name)
A9: 31 | B9: ZS the Coder has recently found an interesting concept called the Birthday Paradox. It states that given a random set of 23 people, there is around 50% chance that some two of them share the same birthday. ZS the Coder finds this very interesting, and decides to test this with the inhabitants of Udayland. In Udayland, there are 2^{n} days in a year. ZS the Coder wants to interview k people from Udayland, each of them has birthday in one of 2^{n} days (each day with equal probability). He is interested in the probability of at least two of them have the birthday at the same day. ZS the Coder knows that the answer can be written as an irreducible fraction $\frac{A}{B}$. He wants to find the values of A and B (he does not like to deal with floating point numbers). Can you help him? -----Input----- The first and only line of the input contains two integers n and k (1 ≤ n ≤ 10^18, 2 ≤ k ≤ 10^18), meaning that there are 2^{n} days in a year and that ZS the Coder wants to interview exactly k people. -----Output----- If the probability of at least two k people having the same birthday in 2^{n} days long year equals $\frac{A}{B}$ (A ≥ 0, B ≥ 1, $\operatorname{gcd}(A, B) = 1$), print the A and B in a single line. Since these numbers may be too large, print them modulo 10^6 + 3. Note that A and B must be coprime before their remainders modulo 10^6 + 3 are taken. -----Examples----- Input 3 2 Output 1 8 Input 1 3 Output 1 1 Input 4 3 Output 23 128 -----Note----- In the first sample case, there are 2^3 = 8 days in Udayland. The probability that 2 people have the same birthday among 2 people is clearly $\frac{1}{8}$, so A = 1, B = 8. In the second sample case, there are only 2^1 = 2 days in Udayland, but there are 3 people, so it is guaranteed that two of them have the same birthday. Thus, the probability is 1 and A = B = 1. | C9: import math def comb(n, r): return math.gcd(math.factorial(n) // (math.factorial(r) * math.factorial(n-r)), 1000000003) n, k = map(int, input().split()) if k > (1 << n): print(-1) else: num = 1 denom = (1 << n) for i in range(1, k+1): num = (num * (denom - comb(denom, i) + comb(denom, i))) % (1000000003) print(num, denom) | D9: B | E9: https://codeforces.com/problemset/problem/711/E | F9: ## Problem ### Problem Description ZS the Coder has recently found an interesting concept called the Birthday Paradox. It states that given a random set of 23 people, there is around 50% chance that some two of them share the same birthday. ZS the Coder finds this very interesting, and decides to test this with the inhabitants of Udayland. In Udayland, there are 2^{n} days in a year. ZS the Coder wants to interview k people from Udayland, each of them has birthday in one of 2^{n} days (each day with equal probability). He is interested in the probability of at least two of them have the birthday at the same day. ZS the Coder knows that the answer can be written as an irreducible fraction $\frac{A}{B}$. He wants to find the values of A and B (he does not like to deal with floating point numbers). Can you help him? -----Input----- The first and only line of the input contains two integers n and k (1 ≤ n ≤ 10^18, 2 ≤ k ≤ 10^18), meaning that there are 2^{n} days in a year and that ZS the Coder wants to interview exactly k people. -----Output----- If the probability of at least two k people having the same birthday in 2^{n} days long year equals $\frac{A}{B}$ (A ≥ 0, B ≥ 1, $\operatorname{gcd}(A, B) = 1$), print the A and B in a single line. Since these numbers may be too large, print them modulo 10^6 + 3. Note that A and B must be coprime before their remainders modulo 10^6 + 3 are taken. -----Examples----- Input 3 2 Output 1 8 Input 1 3 Output 1 1 Input 4 3 Output 23 128 -----Note----- In the first sample case, there are 2^3 = 8 days in Udayland. The probability that 2 people have the same birthday among 2 people is clearly $\frac{1}{8}$, so A = 1, B = 8. In the second sample case, there are only 2^1 = 2 days in Udayland, but there are 3 people, so it is guaranteed that two of them have the same birthday. Thus, the probability is 1 and A = B = 1. ### Solution code file content to be Judged import math def comb(n, r): return math.gcd(math.factorial(n) // (math.factorial(r) * math.factorial(n-r)), 1000000003) n, k = map(int, input().split()) if k > (1 << n): print(-1) else: num = 1 denom = (1 << n) for i in range(1, k+1): num = (num * (denom - comb(denom, i) + comb(denom, i))) % (1000000003) print(num, denom) | G9: Mixtral | H9: 140 | I9: APPS/test/0031 | J9: {'input': '500001 1000003\n', 'expected': '256 256', 'actual': ''} | K9: B | L9: 0 AC, 0 WA, 139 CE, 0 RE, 0 TLE | M9: CE | N9: WA | O9: C | P9: STEP 1: The problem requires calculating the probability that at least two out of k people have the same birthday in a year with 2^n days. The probability should be expressed as an irreducible fraction A/B, and the result should be given modulo 10^6 + 3. STEP 2: Analyzing the code: - The function `comb(n, r)` is defined to calculate the greatest common divisor (GCD) of the binomial coefficient C(n, r) and 1000000003. However, this is not the correct use of the binomial coefficient in this context. - The input is read and split into integers n and k. - The code checks if k is greater than 2^n. If so, it prints -1. This is incorrect because the problem states that if k > 2^n, the probability is 1 (since at least two people must share a birthday). - The code initializes `num` to 1 and `denom` to 2^n. - A loop runs from 1 to k, but the logic inside the loop is incorrect. It attempts to calculate a probability using the `comb` function, which is not correctly implemented for this purpose. - Finally, it prints `num` and `denom`, but these values do not represent the correct probability. STEP 3: The code is incorrect because it does not correctly calculate the probability of at least two people sharing a birthday. The use of the `comb` function is incorrect, and the logic for calculating the probability is flawed. STEP 4: A specific test case that causes the code to fail is n = 1, k = 3. The correct output should be 1 1, but the code will not produce this result. STEP 5: The root cause of the failure is the incorrect implementation of the probability calculation. The code does not correctly handle the case where k > 2^n, and the use of the `comb` function is not appropriate for this problem. Verdict: WA (Wrong Answer) Answer: C | Q9: =_xlfn.XLOOKUP(H9,'final verdict'!F:F,'final verdict'!AJ:AJ,"") -> Misjudged compilation error as wrong answer: indentation issue
